Workbook

Sheet raw

Sheet Sheet1
A1: S.No | B1: Stock | C1: CMP | D1: 50 DMA | E1: 200 DMA | F1: 50 DMA Prev | G1: 200 DMA Prev | H1: 52w High | I1: 52w Low | J1: % from 52w High | K1: % from 52w Low | L1: Vol 1d | M1: Avg Vol 1Wk | N1: Avg Vol 1M | O1: Vol Strength 1W | P1: Vol Strength 1M | Q1: CMP > 50 DMA | R1: CMP > 200 DMA | S1: 50 DMA > 200 DMA | T1: Trend Signal | U1: Trend Class | V1: 1D Return % | W1: 1W Return % | X1: 1M Return % | Y1: 1Y Return % | Z1: Market Cap | AA1: Is SME
A2: 1 | B2: UltraTech Cem. | C2: 11849 | D2: 12181.66 | E2: 11879.73 | F2: 12195.24 | G2: 11880.04 | H2: 13101.8 | I2: 10047.85 | J2: =C2/H2-1 -> -0.095620449 | K2: =C2/I2-1 -> 0.17925725 | L2: 149269 | M2: 167837 | N2: 235677 | O2: =L2/M2 -> 0.88936885 | P2: =L2/N2 -> 0.63336261 | Q2: =IF(C2>D2,"Yes","No") -> No | R2: =IF(C2>E2,"Yes","No") -> No | S2: =IF(D2>E2,"Yes","No") -> Yes | T2: =IF(D2>E2,"Golden Cross","Death Cross") -> Golden Cross | U2: =IF(AND(C2>D2,D2>E2),"Strong Uptrend",IF(C2>D2,"Weak Uptrend",IF(C2<E2,"Downtrend","Neutral"))) -> Downtrend | V2: -0.51 | W2: -0.82 | X2: -2.81 | Y2: 7.3 | Z2: 349165.35 | AA2: 0
A3: 2 | B3: Grasim Inds | C3: 2724.6 | D3: 2823.07 | E3: 2714.08 | F3: 2827.09 | G3: 2713.97 | H3: 2978.85 | I3: 2276.1 | J3: =C3/H3-1 -> -0.08535173 | K3: =C3/I3-1 -> 0.19704758 | L3: 1119848 | M3: 926306 | N3: 601504 | O3: =L3/M3 -> 1.2089396 | P3: =L3/N3 -> 1.8617466 | Q3: =IF(C3>D3,"Yes","No") -> No | R3: =IF(C3>E3,"Yes","No") -> Yes | S3: =IF(D3>E3,"Yes","No") -> Yes | T3: =IF(D3>E3,"Golden Cross","Death Cross") -> Golden Cross | U3: =IF(AND(C3>D3,D3>E3),"Strong Uptrend",IF(C3>D3,"Weak Uptrend",IF(C3<E3,"Downtrend","Neutral"))) -> Neutral | V3: 0.91 | W3: -5.78 | X3: -3.06 | Y3: 7.06 | Z3: 185414.47 | AA3: 0
A4: 3 | B4: Ambuja Cements | C4: 558.8 | D4: 569.9 | E4: 566.19 | F4: 570.36 | G4: 566.26 | H4: 625 | I4: 452.9 | J4: =C4/H4-1 -> -0.10592 | K4: =C4/I4-1 -> 0.23382645 | L4: 1678000 | M4: 3531656 | N4: 2095853 | O4: =L4/M4 -> 0.47513121 | P4: =L4/N4 -> 0.80062867 | Q4: =IF(C4>D4,"Yes","No") -> No | R4: =IF(C4>E4,"Yes","No") -> No | S4: =IF(D4>E4,"Yes","No") -> Yes | T4: =IF(D4>E4,"Golden Cross","Death Cross") -> Golden Cross | U4: =IF(AND(C4>D4,D4>E4),"Strong Uptrend",IF(C4>D4,"Weak Uptrend",IF(C4<E4,"Downtrend","Neutral"))) -> Downtrend | V4: 0.07 | W4: -1.17 | X4: -1.25 | Y4: -1.08 | Z4: 138125.5 | AA4: 0
A5: 4 | B5: Shree Cement | C5: 27375 | D5: 29234.09 | E5: 29170.07 | F5: 29309.97 | G5: 29188.11 | H5: 32508.2 | I5: 23500 | J5: =C5/H5-1 -> -0.15790477 | K5: =C5/I5-1 -> 0.16489362 | L5: 23263 | M5: 15999 | N5: 24037 | O5: =L5/M5 -> 1.4540284 | P5: =L5/N5 -> 0.96779964 | Q5: =IF(C5>D5,"Yes","No") -> No | R5: =IF(C5>E5,"Yes","No") -> No | S5: =IF(D5>E5,"Yes","No") -> Yes | T5: =IF(D5>E5,"Golden Cross","Death Cross") -> Golden Cross | U5: =IF(AND(C5>D5,D5>E5),"Strong Uptrend",IF(C5>D5,"Weak Uptrend",IF(C5<E5,"Downtrend","Neutral"))) -> Downtrend | V5: -0.27 | W5: -3.3 | X5: -7.16 | Y5: 11.58 | Z5: 98771.05 | AA5: 0
A6: 5 | B6: J K Cements | C6: 5636 | D6: 6395.66 | E6: 5875.53 | F6: 6426.67 | G6: 5877.93 | H6: 7565.5 | I6: 3891.45 | J6: =C6/H6-1 -> -0.25503932 | K6: =C6/I6-1 -> 0.44830333 | L6: 124457 | M6: 229925 | N6: 124402 | O6: =L6/M6 -> 0.5412939 | P6: =L6/N6 -> 1.0004421 | Q6: =IF(C6>D6,"Yes","No") -> No | R6: =IF(C6>E6,"Yes","No") -> No | S6: =IF(D6>E6,"Yes","No") -> Yes | T6: =IF(D6>E6,"Golden Cross","Death Cross") -> Golden Cross | U6: =IF(AND(C6>D6,D6>E6),"Strong Uptrend",IF(C6>D6,"Weak Uptrend",IF(C6<E6,"Downtrend","Neutral"))) -> Downtrend | V6: -1.16 | W6: -9.3 | X6: -14.36 | Y6: 38.09 | Z6: 43548.39 | AA6: 0
A7: 6 | B7: Dalmia BharatLtd | C7: 2037.5 | D7: 2206.09 | E7: 2112.85 | F7: 2212.97 | G7: 2113.61 | H7: 2496.3 | I7: 1601 | J7: =C7/H7-1 -> -0.18379201 | K7: =C7/I7-1 -> 0.2726421 | L7: 90092 | M7: 197223 | N7: 368810 | O7: =L7/M7 -> 0.45680271 | P7: =L7/N7 -> 0.24427754 | Q7: =IF(C7>D7,"Yes","No") -> No | R7: =IF(C7>E7,"Yes","No") -> No | S7: =IF(D7>E7,"Yes","No") -> Yes | T7: =IF(D7>E7,"Golden Cross","Death Cross") -> Golden Cross | U7: =IF(AND(C7>D7,D7>E7),"Strong Uptrend",IF(C7>D7,"Weak Uptrend",IF(C7<E7,"Downtrend","Neutral"))) -> Downtrend | V7: -0.55 | W7: -2.83 | X7: -8.82 | Y7: 15.24 | Z7: 38216.4 | AA7: 0
A8: 7 | B8: ACC | C8: 1840.5 | D8: 1854.01 | E8: 1932.71 | F8: 1854.56 | G8: 1933.64 | H8: 2324.95 | I8: 1775.05 | J8: =C8/H8-1 -> -0.20837007 | K8: =C8/I8-1 -> 0.036872201 | L8: 252622 | M8: 444388 | N8: 298806 | O8: =L8/M8 -> 0.5684717 | P8: =L8/N8 -> 0.84543818 | Q8: =IF(C8>D8,"Yes","No") -> No | R8: =IF(C8>E8,"Yes","No") -> No | S8: =IF(D8>E8,"Yes","No") -> No | T8: =IF(D8>E8,"Golden Cross","Death Cross") -> Death Cross | U8: =IF(AND(C8>D8,D8>E8),"Strong Uptrend",IF(C8>D8,"Weak Uptrend",IF(C8<E8,"Downtrend","Neutral"))) -> Downtrend | V8: 0.44 | W8: -2.18 | X8: -1.83 | Y8: -19.68 | Z8: 34562.25 | AA8: 0
D12: Shareholders Patter | E12: 2024
D13: Promoters | E13: 0.5996
D14: FIIs | E14: 0.1774
D15: DIIs | E15: 0.1414
D16: Public | E16: 0.0792

Sheet Index
G3: Valuation Model oF UltraTech Cement Ltd.
D9: Company Name | F9: UltraTech Cement Ltd. | G9: Blue | H9: Hard coded numbers
D10: Parent Organization | F10: Aditya Birla Group | G10: Black | H10: Formulas
D11: Headquarters | F11: Mumbai | G11: Green | H11: Link to the other Worksheet
D12: Founder | F12: Kumar Mangalam Birla | G12: Red | H12: External File Links
D14: Sheet No | F14: Sheet Name | G14: Link to the Sheet
D15: 1 | F15: Index (This Sheet) | G15: Index
D16: 2 | F16: Overview | G16: Overview
D17: 3 | F17: Comparative Company Analysis | G17: Comparative Company Analysis
D18: 4 | F18: Ratios | G18: Ratios
D19: 5 | F19: Drivers of the Model | G19: Drivers
D20: 6 | F20: Income Statement | G20: IS
D21: 7 | F21: Balance Sheet | G21: BS
D22: 8 | F22: Cash Flow Statement | G22: CFS
D23: 9 | F23: Property, Plant, and Equipment | G23: PPE
D24: 10 | F24: Working Capital | G24: WS
D25: 11 | F25: Weighted Average Cost Of Capital | G25: WACC
D26: 12 | F26: Discounted Cash Flow Statement | G26: DCF
... D29: 15 | F29: Cash Flow Statement (Source) | G29: (CFS)

Sheet Overview
T1: Index
B2: Overview
C5: Company Data | H5: Financial Snapshot (Rs. Cr) | I5: 2024A | J5: 2025E | K5: 2026E | L5: 2027E | P5: Ratios | Q5: 2024A | R5: 2025E | S5: 2026E | T5: 2027E
C6: Market Cap (Rs. Cr) | D6: =Comparative!D7 -> 305271 | H6: Sales | I6: =IS!G5 -> 70908.14 | J6: =IS!H5 -> 82749.799 | K6: =IS!I5 -> 96569.016 | L6: =IS!J5 -> 111730.35 | P6: EBIDTAM (%) | Q6: =Ratios!G11 -> 0.1908881 | R6: =Ratios!H11 -> 0.22564672 | S6: =Ratios!I11 -> 0.22598669 | T6: =Ratios!J11 -> 0.22365526
C7: Outstanding Shares (cr) | D7: =Comparative!E7 -> 28.853592 | H7: EBIDTA | I7: =IS!G13 -> 13535.52 | J7: =IS!H13 -> 18672.221 | K7: =IS!I13 -> 21823.313 | L7: =IS!J13 -> 24989.081 | P7: NPM (%) | Q7: =Ratios!G14 -> 0.098775119 | R7: =Ratios!H14 -> 0.12919715 | S7: =Ratios!I14 -> 0.13342656 | T7: =Ratios!J14 -> 0.13445713
C8: Current Market Price | D8: =D6/D7 -> 10580 | H8: PAT | I8: =IS!G19 -> 7003.96 | J8: =IS!H19 -> 10691.038 | K8: =IS!I19 -> 12884.871 | L8: =IS!J19 -> 15022.942 | P8: Debt:Equity (x) | Q8: =Ratios!G20 -> 0.088049897 | R8: =Ratios!H20 -> 0.077468079 | S8: =Ratios!I20 -> 0.067627233 | T8: =Ratios!J20 -> 0.058903801
C9: 52 Week High - Low (Rs.) | D9: 13,102 / 10,048 | H9: EPS | I9: =I8/$D$7 -> 242.74136 | J9: =J8/$D$7 -> 370.52711 | K9: =K8/$D$7 -> 446.56039 | L9: =L8/$D$7 -> 520.66107 | P9: RoE (%) | Q9: =Ratios!G17 -> 0.11618274 | R9: =Ratios!H17 -> 0.15561111 | S9: =Ratios!I17 -> 0.16352121 | T9: =Ratios!J17 -> 0.16634543
C10: Enterprise Value (Rs. Cr) | D10: =Comparative!I7 -> 321452 | P10: RoCE (%) | Q10: =Ratios!G18 -> 0.15840682 | R10: =Ratios!H18 -> 0.20480675 | S10: =Ratios!I18 -> 0.21505669 | T10: =Ratios!J18 -> 0.21897415
C11: Book Value (Rs. Cr) | D11: =BS!G36/Comparative!E7 -> 2089.3066 | P11: P/E (x) | Q11: =Comparative!Q7 -> 43.585237 | R11: 29.5 | S11: 24.5 | T11: 21
C12: Beta | D12: =WAAC!C17 -> 0.56 | P12: P/BV (x) | Q12: =D8/D11 -> 5.063881 | R12: 4.6 | S12: 4 | T12: 3.5
C13: Face Value (Rs.) | D13: 10 | H13: Share Price Movement on NSE | P13: EV/EBIDTA (x) | Q13: =$D$10/IS!G13 -> 23.748774 | R13: =$D$10/IS!H13 -> 17.21552 | S13: =$D$10/IS!I13 -> 14.729753 | T13: =$D$10/IS!J13 -> 12.863699
C17: Product Segments | P17: Shareholding Pattern
C18: Segment | D18: Share
C19: Grey Cement - Domestic | D19: 0.8
C20: Ready-mix Concrete | D20: 0.09
C21: Overseas Business | D21: 0.05
C22: White Cement | D22: 0.03
C23: Other | D23: 0.02

Sheet Comparative
B2: Comparative Industrial Analysis | K2: Index
B3: All figures in Rs.Crores
C4: Market Data | K4: Financials | O4: Valuation
B5: Company | C5: Share Price Re./Share | D5: Equity Value (Market Cap) | E5: No.of Shares Outstanding | F5: Debt | G5: Cash Equi | H5: Net Debt | I5: Enterprise Value | K5: Revenue | L5: EBIDTA | M5: Net income | O5: EV/Revenue | P5: EV/EBIDTA | Q5: P/E
B7: UltraTech Cem. | C7: 10580 | D7: 305271 | E7: =D7/C7 -> 28.853592 | F7: 16964 | G7: 783 | H7: =F7-G7 -> 16181 | I7: =D7+H7 -> 321452 | K7: 70908 | L7: 13509 | M7: 7004 | O7: =I7/K7 -> 4.5333672 | P7: =I7/L7 -> 23.795396 | Q7: =D7/M7 -> 43.585237
B8: Ambuja Cements | C8: 536.25 | D8: 132171 | E8: =D8/C8 -> 246.47273 | F8: 779 | G8: 11069 | H8: =F8-G8 -> -10290 | I8: =D8+H8 -> 121881 | K8: 33160 | L8: 7456 | M8: 4738 | O8: =I8/K8 -> 3.6755428 | P8: =I8/L8 -> 16.346701 | Q8: =D8/M8 -> 27.895948
B9: Shree Cement | C9: 25315.45 | D9: 91368 | E9: =D9/C9 -> 3.6091794 | F9: 1682 | G9: 422 | H9: =F9-G9 -> 1260 | I9: =D9+H9 -> 92628 | K9: 20521 | L9: 5129 | M9: 2396 | O9: =I9/K9 -> 4.5138151 | P9: =I9/L9 -> 18.059661 | Q9: =D9/M9 -> 38.133556
B10: ACC | C10: 2014.9 | D10: 37846 | E10: =D10/C10 -> 18.783066 | F10: 457 | G10: 1863 | H10: =F10-G10 -> -1406 | I10: =D10+H10 -> 36440 | K10: 19959 | L10: 3559 | M10: 2337 | O10: =I10/K10 -> 1.8257428 | P10: =I10/L10 -> 10.238831 | Q10: =D10/M10 -> 16.194266
B11: J K Cements | C11: 4541.2 | D11: 35047 | E11: =D11/C11 -> 7.7175636 | F11: 5738 | G11: 867 | H11: =F11-G11 -> 4871 | I11: =D11+H11 -> 39918 | K11: 11556 | L11: 2216 | M11: 790 | O11: =I11/K11 -> 3.4543094 | P11: =I11/L11 -> 18.013538 | Q11: =D11/M11 -> 44.363291
B12: Dalmia BharatLtd | C12: 1721.95 | D12: 32226 | E12: =D12/C12 -> 18.714829 | F12: 4931 | G12: 582 | H12: =F12-G12 -> 4349 | I12: =D12+H12 -> 36575 | K12: 14691 | L12: 2871 | M12: 853 | O12: =I12/K12 -> 2.4896195 | P12: =I12/L12 -> 12.739464 | Q12: =D12/M12 -> 37.779601
B13: The Ramco Cement | C13: 883.95 | D13: 20902 | E13: =D13/C13 -> 23.646134 | F13: 5223 | G13: 137 | H13: =F13-G13 -> 5086 | I13: =D13+H13 -> 25988 | K13: 9376 | L13: 1600 | M13: 356 | O13: =I13/K13 -> 2.7717577 | P13: =I13/L13 -> 16.2425 | Q13: =D13/M13 -> 58.713483
B14: Nuvoco Vistas | C14: 349.95 | D14: 12509 | E14: =D14/C14 -> 35.745106 | F14: 4862 | G14: 107 | H14: =F14-G14 -> 4755 | I14: =D14+H14 -> 17264 | K14: 10733 | L14: 1650 | M14: 147 | O14: =I14/K14 -> 1.6084972 | P14: =I14/L14 -> 10.46303 | Q14: =D14/M14 -> 85.095238
A15: O | B15: India Cements | C15: 379.1 | D15: 11751 | E15: =D15/C15 -> 30.997098 | F15: 2137 | G15: 84 | H15: =F15-G15 -> 2053 | I15: =D15+H15 -> 13804 | K15: 5112 | L15: 159 | M15: 227 | O15: =I15/K15 -> 2.700313 | P15: =I15/L15 -> 86.81761 | Q15: =D15/M15 -> 51.76652
B16: JK Lakshmi Cem. | C16: 787.9 | D16: 9271 | E16: =D16/C16 -> 11.766722 | F16: 2262 | G16: 267 | H16: =F16-G16 -> 1995 | I16: =D16+H16 -> 11266 | K16: 6788 | L16: 1112 | M16: 488 | O16: =I16/K16 -> 1.6596936 | P16: =I16/L16 -> 10.131295 | Q16: =D16/M16 -> 18.997951
B18: High | O18: =MAX(O8:O16) -> 4.5138151 | P18: =MAX(P8:P16) -> 86.81761 | Q18: =MAX(Q8:Q16) -> 85.095238
B19: 75th Percentile | O19: =QUARTILE(O8:O16,3) -> 3.4543094 | P19: =QUARTILE(P8:P16,3) -> 18.013538 | Q19: =QUARTILE(Q8:Q16,3) -> 51.76652
A20: O | B20: Average | O20: =AVERAGE(O8:O16) -> 2.7443657 | P20: =AVERAGE(P8:P16) -> 22.116959 | Q20: =AVERAGE(Q8:Q16) -> 42.104428
A21: F | B21: Median | O21: =MEDIAN(O8:O16) -> 2.700313 | P21: =MEDIAN(P8:P16) -> 16.2425 | Q21: =MEDIAN(Q8:Q16) -> 38.133556
B22: 25th Percentile | O22: =QUARTILE(O8:O16,1) -> 1.8257428 | P22: =QUARTILE(P8:P16,1) -> 10.46303 | Q22: =QUARTILE(Q8:Q16,1) -> 27.895948
B23: Low | O23: =MIN(O8:O16) -> 1.6084972 | P23: =MIN(P8:P16) -> 10.131295 | Q23: =MIN(Q8:Q16) -> 16.194266
B25: Tata Motors Valuation | O25: EV/Revenue | P25: EV/EBIDTA | Q25: P/E
B26: Implied Enterprise Value | O26: =O21*K7 -> 191473.79 | P26: =P21*L7 -> 219419.93 | Q26: =Q27+Q28 -> 267870.43
B27: Net Debt | O27: =$G$7 -> 783 | P27: =$G$7 -> 783 | Q27: =$G$7 -> 783
B28: Implied Market V alue | O28: =O26-O27 -> 190690.79 | P28: =P26-P27 -> 218636.93 | Q28: =Q21*M7 -> 267087.43
B29: Shares Outstanding | O29: =E7 -> 28.853592 | P29: =O29 -> 28.853592 | Q29: =P29 -> 28.853592
B30: Implied Value Per Share | O30: =O28/O29 -> 6608.9101 | P30: =P28/P29 -> 7577.4598 | Q30: =Q28/Q29 -> 9256.644

Sheet Ratios
B2: Ratios | K2: Index
B3: All figures in Rs.Crores
B4: Financial Year | C4: 43891 | D4: 44256 | E4: 44621 | F4: 44986 | G4: 45352 | H4: 45717 | I4: 46082 | J4: 46447 | K4: 46813 | L4: 47178 | M4: Trend | N4: Mean | O4: Median
B5: Sales Growth (%) | D5: =(IS!D5-IS!C5)/IS!C5 -> 0.054110675 | E5: =(IS!E5-IS!D5)/IS!D5 -> 0.17602882 | F5: =(IS!F5-IS!E5)/IS!E5 -> 0.20230773 | G5: =(IS!G5-IS!F5)/IS!F5 -> 0.12125494 | H5: =(IS!H5-IS!G5)/IS!G5 -> 0.167 | I5: =(IS!I5-IS!H5)/IS!H5 -> 0.167 | J5: =(IS!J5-IS!I5)/IS!I5 -> 0.157 | K5: =(IS!K5-IS!J5)/IS!J5 -> 0.147 | L5: =(IS!L5-IS!K5)/IS!K5 -> 0.137 | N5: =AVERAGE(C5:L5) -> 0.14763357 | O5: =MEDIAN(C5:L5) -> 0.157
B6: EBITDA Growth (%) | D6: =(IS!D13-IS!C13)/IS!C13 -> 0.23132192 | E6: =(IS!E13-IS!D13)/IS!D13 -> -0.00021745499 | F6: =(IS!F13-IS!E13)/IS!E13 -> -0.086739912 | G6: =(IS!G13-IS!F13)/IS!F13 -> 0.21646164 | H6: =(IS!H13-IS!G13)/IS!G13 -> 0.37949786 | I6: =(IS!I13-IS!H13)/IS!H13 -> 0.16875827 | J6: =(IS!J13-IS!I13)/IS!I13 -> 0.14506359 | K6: =(IS!K13-IS!J13)/IS!J13 -> 0.12010874 | L6: =(IS!L13-IS!K13)/IS!K13 -> 0.095248714 | N6: =AVERAGE(C6:L6) -> 0.14105593 | O6: =MEDIAN(C6:L6) -> 0.14506359
B7: EBIT Growth (%) | D7: =(IS!D15-IS!C15)/IS!C15 -> 0.32223457 | E7: =(IS!E15-IS!D15)/IS!D15 -> -0.0018099977 | F7: =(IS!F15-IS!E15)/IS!E15 -> -0.12990349 | G7: =(IS!G15-IS!F15)/IS!F15 -> 0.26110667 | H7: =(IS!H15-IS!G15)/IS!G15 -> 0.459161 | I7: =(IS!I15-IS!H15)/IS!H15 -> 0.19330273 | J7: =(IS!J15-IS!I15)/IS!I15 -> 0.15748369 | K7: =(IS!K15-IS!J15)/IS!J15 -> 0.12606618 | L7: =(IS!L15-IS!K15)/IS!K15 -> 0.096780125 | N7: =AVERAGE(C7:L7) -> 0.16493572 | O7: =MEDIAN(C7:L7) -> 0.15748369
B8: PAT Growth (%) | D8: =(IS!D19-IS!C19)/IS!C19 -> -0.050258395 | E8: =(IS!E19-IS!D19)/IS!D19 -> 0.34281608 | F8: =(IS!F19-IS!E19)/IS!E19 -> -0.30826014 | G8: =(IS!G19-IS!F19)/IS!F19 -> 0.38052588 | H8: =(IS!H19-IS!G19)/IS!G19 -> 0.52642762 | I8: =(IS!I19-IS!H19)/IS!H19 -> 0.20520301 | J8: =(IS!J19-IS!I19)/IS!I19 -> 0.16593651 | K8: =(IS!K19-IS!J19)/IS!J19 -> 0.13214073 | L8: =(IS!L19-IS!K19)/IS!K19 -> 0.099878056 | N8: =AVERAGE(C8:L8) -> 0.16604549 | O8: =MEDIAN(C8:L8) -> 0.16593651
B10: Gross Margin (%) | C10: =IS!C7/IS!C5 -> 0.77465508 | D10: =IS!D7/IS!D5 -> 0.77299031 | E10: =IS!E7/IS!E5 -> 0.77462122 | F10: =IS!F7/IS!F5 -> 0.77768336 | G10: =IS!G7/IS!G5 -> 0.76305837 | H10: =IS!H7/IS!H5 -> 0.77260167 | I10: =IS!I7/IS!I5 -> 0.77260167 | J10: =IS!J7/IS!J5 -> 0.77260167 | ... L10: =IS!L7/IS!L5 -> 0.77260167 | N10: =AVERAGE(C10:L10) -> 0.77260167 | O10: =MEDIAN(C10:L10) -> 0.77260167
B11: EBITDA Margin (%) | C11: =IS!C13/IS!C5 -> 0.23325608 | D11: =IS!D13/IS!D5 -> 0.2724698 | E11: =IS!E13/IS!E5 -> 0.23163595 | F11: =IS!F13/IS!F5 -> 0.17594819 | G11: =IS!G13/IS!G5 -> 0.1908881 | H11: =IS!H13/IS!H5 -> 0.22564672 | I11: =IS!I13/IS!I5 -> 0.22598669 | J11: =IS!J13/IS!J5 -> 0.22365526 | ... L11: =IS!L13/IS!L5 -> 0.21039149 | N11: =AVERAGE(C11:L11) -> 0.220829 | O11: =MEDIAN(C11:L11) -> 0.22465099
B12: EBIT Margin (%) | C12: =IS!C15/IS!C5 -> 0.16908764 | D12: =IS!D15/IS!D5 -> 0.21209682 | E12: =IS!E15/IS!E5 -> 0.18002359 | F12: =IS!F15/IS!F5 -> 0.13028103 | G12: =IS!G15/IS!G5 -> 0.14653071 | H12: =IS!H15/IS!H5 -> 0.18321499 | I12: =IS!I15/IS!I5 -> 0.18734443 | J12: =IS!J15/IS!J5 -> 0.18742275 | ... L12: =IS!L15/IS!L5 -> 0.17749328 | N12: =AVERAGE(C12:L12) -> 0.17574973 | O12: =MEDIAN(C12:L12) -> 0.18161929
B13: EBT Margin (%) | C13: =IS!C17/IS!C5 -> 0.12214785 | D13: =IS!D17/IS!D5 -> 0.17887998 | E13: =IS!E17/IS!E5 -> 0.16206292 | F13: =IS!F17/IS!F5 -> 0.11727154 | G13: =IS!G17/IS!G5 -> 0.13287924 | H13: =IS!H17/IS!H5 -> 0.17226286 | I13: =IS!I17/IS!I5 -> 0.17790208 | J13: =IS!J17/IS!J5 -> 0.17927617 | ... L13: =IS!L17/IS!L5 -> 0.1711763 | N13: =AVERAGE(C13:L13) -> 0.15908126 | O13: =MEDIAN(C13:L13) -> 0.17171958
A14: O | B14: Net Profit Margin (%) | C14: =IS!C19/IS!C5 -> 0.13553841 | D14: =IS!D19/IS!D5 -> 0.12211855 | E14: =IS!E19/IS!E5 -> 0.1394377 | F14: =IS!F19/IS!F5 -> 0.080224567 | G14: =IS!G19/IS!G5 -> 0.098775119 | H14: =IS!H19/IS!H5 -> 0.12919715 | I14: =IS!I19/IS!I5 -> 0.13342656 | J14: =IS!J19/IS!J5 -> 0.13445713 | ... L14: =IS!L19/IS!L5 -> 0.12838222 | N14: =AVERAGE(C14:L14) -> 0.12342727 | O14: =MEDIAN(C14:L14) -> 0.1309562
B16: ROA | C16: =IS!C19/BS!C19 -> 0.072597455 | D16: =IS!D19/BS!D19 -> 0.063380175 | E16: =IS!E19/BS!E19 -> 0.087507427 | F16: =IS!F19/BS!F19 -> 0.055520415 | G16: =IS!G19/BS!G19 -> 0.069485798 | H16: =IS!H19/BS!H19 -> 0.097426113 | I16: =IS!I19/BS!I19 -> 0.10595894 | J16: =IS!J19/BS!J19 -> 0.11169242 | ... L16: =IS!L19/BS!L19 -> 0.11274049 | N16: =AVERAGE(C16:L16) -> 0.089019002 | O16: =MEDIAN(C16:L16) -> 0.09246677
B17: ROE | C17: =IS!C19/(BS!C36) -> 0.14725457 | D17: =IS!D19/(BS!D36) -> 0.12362441 | E17: =IS!E19/(BS!E36) -> 0.14542581 | F17: =IS!F19/(BS!F36) -> 0.093295329 | G17: =IS!G19/(BS!G36) -> 0.11618274 | H17: =IS!H19/(BS!H36) -> 0.15561111 | I17: =IS!I19/(BS!I36) -> 0.16352121 | J17: =IS!J19/(BS!J36) -> 0.16634543 | ... L17: =IS!L19/(BS!L36) -> 0.15884038 | N17: =AVERAGE(C17:L17) -> 0.14347876 | O17: =MEDIAN(C17:L17) -> 0.15143284
B18: ROCE | C18: =IS!C15/(BS!C36+BS!C27) -> 0.12715554 | D18: =IS!D15/(BS!D36+BS!D27) -> 0.16432296 | E18: =IS!E15/(BS!E36+BS!E27) -> 0.16989073 | F18: =IS!F15/(BS!F36+BS!F27) -> 0.13792303 | G18: =IS!G15/(BS!G36+BS!G27) -> 0.15840682 | H18: =IS!H15/(BS!H36+BS!H27) -> 0.20480675 | I18: =IS!I15/(BS!I36+BS!I27) -> 0.21505669 | J18: =IS!J15/(BS!J36+BS!J27) -> 0.21897415 | ... L18: =IS!L15/(BS!L36+BS!L27) -> 0.21010472 | N18: =AVERAGE(C18:L18) -> 0.18237772 | O18: =MEDIAN(C18:L18) -> 0.18734874
B20: Debt Equity Ratio | C20: =BS!C27/BS!C36 -> 0.44471757 | D20: =BS!D27/BS!D36 -> 0.30664765 | E20: =BS!E27/BS!E36 -> 0.10514941 | F20: =BS!F27/BS!F36 -> 0.098492093 | G20: =BS!G27/BS!G36 -> 0.088049897 | H20: =BS!H27/BS!H36 -> 0.077468079 | I20: =BS!I27/BS!I36 -> 0.067627233 | J20: =BS!J27/BS!J36 -> 0.058903801 | ... L20: =BS!L27/BS!L36 -> 0.045206551 | N20: =AVERAGE(C20:L20) -> 0.13438099 | O20: =MEDIAN(C20:L20) -> 0.082758988
A21: O | B21: Interest Coverage Ratio | C21: =IS!C15/IS!C16 -> 3.6022243 | D21: =IS!D15/IS!D16 -> 6.3852186 | E21: =IS!E15/IS!E16 -> 10.023213 | F21: =IS!F15/IS!F16 -> 10.014306 | G21: =IS!G15/IS!G16 -> 10.733698 | H21: =IS!H15/IS!H16 -> 16.728711 | I21: =IS!I15/IS!I16 -> 19.840859 | J21: =IS!J15/IS!J16 -> 23.006303 | ... L21: =IS!L15/IS!L16 -> 28.097808 | N21: =AVERAGE(C21:L21) -> 15.453769 | O21: =MEDIAN(C21:L21) -> 13.731205
A22: F
B23: Current Rato | C23: =BS!C10/BS!C25 -> 0.71598663 | D23: =BS!D10/BS!D25 -> 0.62098108 | E23: =BS!E10/BS!E25 -> 0.63763389 | F23: =BS!F10/BS!F25 -> 0.67129174 | G23: =BS!G10/BS!G25 -> 0.67031259 | H23: =BS!H10/BS!H25 -> 0.78243597 | I23: =BS!I10/BS!I25 -> 0.90160237 | J23: =BS!J10/BS!J25 -> 1.0149752 | ... L23: =BS!L10/BS!L25 -> 1.3065943 | N23: =AVERAGE(C23:L23) -> 0.8474487 | O23: =MEDIAN(C23:L23) -> 0.7492113
B24: Quick Ratio | C24: =(BS!C10-BS!C5)/BS!C25 -> 0.51913031 | D24: =(BS!D10-BS!D5)/BS!D25 -> 0.47334191 | E24: =(BS!E10-BS!E5)/BS!E25 -> 0.43022868 | F24: =(BS!F10-BS!F5)/BS!F25 -> 0.4544053 | G24: =(BS!G10-BS!G5)/BS!G25 -> 0.42604539 | H24: =(BS!H10-BS!H5)/BS!H25 -> 0.53542161 | I24: =(BS!I10-BS!I5)/BS!I25 -> 0.62735157 | J24: =(BS!J10-BS!J5)/BS!J25 -> 0.70937844 | ... L24: =(BS!L10-BS!L5)/BS!L25 -> 0.94588844 | N24: =AVERAGE(C24:L24) -> 0.59399618 | O24: =MEDIAN(C24:L24) -> 0.52727596
B25: Cash Ratio | C25: =BS!C7/BS!C25 -> 0.025412961 | D25: =BS!D7/BS!D25 -> 0.07378284 | E25: =BS!E7/BS!E25 -> 0.01330566 | F25: =BS!F7/BS!F25 -> 0.037722233 | G25: =BS!G7/BS!G25 -> 0.02296053 | H25: =BS!H7/BS!H25 -> 0.13399739 | I25: =BS!I7/BS!I25 -> 0.21486084 | J25: =BS!J7/BS!J25 -> 0.28131973 | ... L25: =BS!L7/BS!L25 -> 0.49490652 | N25: =AVERAGE(C25:L25) -> 0.16756933 | O25: =MEDIAN(C25:L25) -> 0.10389012
B27: Debitor Turnover Ratio | D27: =IS!D5/AVERAGE(BS!C6:D6) -> 18.052795 | E27: =IS!E5/AVERAGE(BS!D6:E6) -> 18.638848 | F27: =IS!F5/AVERAGE(BS!E6:F6) -> 18.227405 | G27: =IS!G5/AVERAGE(BS!F6:G6) -> 17.411452 | H27: =IS!H5/AVERAGE(BS!G6:H6) -> 18.114525 | I27: =IS!I5/AVERAGE(BS!H6:I6) -> 18.345317 | J27: =IS!J5/AVERAGE(BS!I6:J6) -> 18.272437 | K27: =IS!K5/AVERAGE(BS!J6:K6) -> 18.198879 | L27: =IS!L5/AVERAGE(BS!K6:L6) -> 18.124632 | N27: =AVERAGE(C27:L27) -> 18.154032 | O27: =MEDIAN(C27:L27) -> 18.198879
B28: Creditor Turnover Ratio | D28: =IS!D6/AVERAGE(BS!C21:D21) -> 2.5668537 | E28: =IS!E6/AVERAGE(BS!E21:F21) -> 1.8137485 | F28: =IS!F6/AVERAGE(BS!F21:G21) -> 1.7924778 | G28: =IS!G6/AVERAGE(BS!G21:H21) -> 1.9561653 | H28: =IS!H6/AVERAGE(BS!H21:I21) -> 1.9963063 | I28: =IS!I6/AVERAGE(BS!I21:J21) -> 2.0055613 | J28: =IS!J6/AVERAGE(BS!J21:K21) -> 2.0149026 | K28: =IS!K6/AVERAGE(BS!K21:L21) -> 2.0243312 | L28: =IS!L6/AVERAGE(BS!L21:M21) -> 2.1629979 | N28: =AVERAGE(C28:L28) -> 2.0370383 | O28: =MEDIAN(C28:L28) -> 2.0055613
B29: Inventory Turnover Ratio | D29: =IS!D6/AVERAGE(BS!C5:D5) -> 2.4760858 | E29: =IS!E6/AVERAGE(BS!D5:E5) -> 2.4661244 | F29: =IS!F6/AVERAGE(BS!E5:F5) -> 2.3032929 | G29: =IS!G6/AVERAGE(BS!F5:G5) -> 2.2488409 | H29: =IS!H6/AVERAGE(BS!G5:H5) -> 2.2297649 | I29: =IS!I6/AVERAGE(BS!H5:I5) -> 2.3709557 | J29: =IS!J6/AVERAGE(BS!I5:J5) -> 2.3615367 | K29: =IS!K6/AVERAGE(BS!J5:K5) -> 2.35203 | L29: =IS!L6/AVERAGE(BS!K5:L5) -> 2.3424344 | N29: =AVERAGE(C29:L29) -> 2.3501184 | O29: =MEDIAN(C29:L29) -> 2.35203
B30: Fixed Asset Turnover | D30: =IS!D6/AVERAGE(PPE!C16:D16) -> 3.7445679 | E30: =IS!E6/AVERAGE(PPE!D16:E16) -> 4.3784686 | F30: =IS!F6/AVERAGE(PPE!E16:F16) -> 5.018723 | G30: =IS!G6/AVERAGE(PPE!F16:G16) -> 5.5694621 | H30: =IS!H6/AVERAGE(PPE!G16:H16) -> 5.6537573 | I30: =IS!I6/AVERAGE(PPE!H16:I16) -> 6.0637994 | J30: =IS!J6/AVERAGE(PPE!I16:J16) -> 6.5315086 | K30: =IS!K6/AVERAGE(PPE!J16:K16) -> 6.8910133 | L30: =IS!L6/AVERAGE(PPE!K16:L16) -> 7.2005137 | N30: =AVERAGE(C30:L30) -> 5.6724238 | O30: =MEDIAN(C30:L30) -> 5.6537573
B31: Capital Turnover Ratio | C31: =IS!C5/(BS!C36+BS!C27) -> 0.75200968 | D31: =IS!D5/(BS!D36+BS!D27) -> 0.77475446 | E31: =IS!E5/(BS!E36+BS!E27) -> 0.94371376 | F31: =IS!F5/(BS!F36+BS!F27) -> 1.0586578 | G31: =IS!G5/(BS!G36+BS!G27) -> 1.0810486 | H31: =IS!H5/(BS!H36+BS!H27) -> 1.1178493 | I31: =IS!I5/(BS!I36+BS!I27) -> 1.1479215 | J31: =IS!J5/(BS!J36+BS!J27) -> 1.1683435 | ... L31: =IS!L5/(BS!L36+BS!L27) -> 1.1837334 | N31: =AVERAGE(C31:L31) -> 1.0408104 | O31: =MEDIAN(C31:L31) -> 1.0994489
B33: Debtor Days | D33: =365/D27 -> 20.218476 | E33: =365/E27 -> 19.582755 | F33: =365/F27 -> 20.024793 | G33: =365/G27 -> 20.963214 | H33: =365/H27 -> 20.149577 | I33: =365/I27 -> 19.896086 | J33: =365/J27 -> 19.975441 | K33: =365/K27 -> 20.05618 | L33: =365/L27 -> 20.138339 | N33: =AVERAGE(C33:L33) -> 20.111651 | O33: =MEDIAN(C33:L33) -> 20.05618
B34: Payable Days | D34: =365/D28 -> 142.19743 | E34: =365/E28 -> 201.24069 | F34: =365/F28 -> 203.62874 | G34: =365/G28 -> 186.58955 | H34: =365/H28 -> 182.83767 | I34: =365/I28 -> 181.99393 | J34: =365/J28 -> 181.1502 | K34: =365/K28 -> 180.30646 | L34: =365/L28 -> 168.74727 | N34: =AVERAGE(C34:L34) -> 180.96577 | O34: =MEDIAN(C34:L34) -> 181.99393
B35: Inventory Days | D35: =365/D29 -> 147.41008 | E35: =365/E29 -> 148.00551 | F35: =365/F29 -> 158.46877 | G35: =365/G29 -> 162.30584 | H35: =365/H29 -> 163.69439 | I35: =365/I29 -> 153.94636 | J35: =365/J29 -> 154.56037 | K35: =365/K29 -> 155.18509 | L35: =365/L29 -> 155.8208 | N35: =AVERAGE(C35:L35) -> 155.48858 | O35: =MEDIAN(C35:L35) -> 155.18509
B36: Cash Conversion Cycle (in days) | D36: =D35+D33-D34 -> 25.431123 | E36: =E35+E33-E34 -> -33.652428 | F36: =F35+F33-F34 -> -25.135172 | G36: =G35+G33-G34 -> -3.3204931 | H36: =H35+H33-H34 -> 1.0062936 | I36: =I35+I33-I34 -> -8.1514866 | J36: =J35+J33-J34 -> -6.6143826 | K36: =K35+K33-K34 -> -5.0651885 | L36: =L35+L33-L34 -> 7.2118665 | N36: =AVERAGE(C36:L36) -> -5.3655409 | O36: =MEDIAN(C36:L36) -> -5.0651885

Sheet Drivers
B1: Scenario | C1: 2
B2: Drivers | K2: Index
B3: All figures in Rs.Crores (Unless Specified)
B4: Financial Year | C4: 44256 | D4: 44621 | E4: 44986 | F4: 45352 | G4: 45717 | H4: 46082 | I4: 46447 | J4: 46813 | K4: 47178 | L4: 47543
B5: Income Statement Drivers
B7: Revenue | C7: =IS!C5 -> 42429.89 | D7: =IS!D5 -> 44725.8 | E7: =IS!E5 -> 52598.83 | F7: =IS!F5 -> 63239.98 | G7: =IS!G5 -> 70908.14
B8: Revenue Growth Y-O-Y | D8: =(D7-C7)/C7 -> 0.054110675 | E8: =(E7-D7)/D7 -> 0.17602882 | F8: =(F7-E7)/E7 -> 0.20230773 | G8: =(G7-F7)/F7 -> 0.12125494 | H8: =CHOOSE($C$1,H9,H10,H11,) -> 0.167 | I8: =CHOOSE($C$1,I9,I10,I11,) -> 0.167 | J8: =CHOOSE($C$1,J9,J10,J11,) -> 0.157 | K8: =CHOOSE($C$1,K9,K10,K11,) -> 0.147 | L8: =CHOOSE($C$1,L9,L10,L11,) -> 0.137
B9: Scenario 1 | C9: - | H9: =H10-2% -> 0.147 | I9: =I10-2% -> 0.147 | J9: =J10-2% -> 0.137 | K9: =K10-2% -> 0.127 | L9: =L10-2% -> 0.117
B10: Scenario 2 | C10: - | H10: ='(IS)'!K38 -> 0.167 | I10: =H10 -> 0.167 | J10: =I10-1% -> 0.157 | K10: =J10-1% -> 0.147 | L10: =K10-1% -> 0.137
B11: Scenario 3 | C11: - | H11: =H10+2% -> 0.187 | I11: =I10+2% -> 0.187 | J11: =J10+2% -> 0.177 | K11: =K10+2% -> 0.167 | L11: =L10+2% -> 0.157
B13: Cost of Goods Sold | C13: =IS!C6 -> 9561.36 | D13: =IS!D6 -> 10153.19 | E13: =IS!E6 -> 11854.66 | F13: =IS!F6 -> 14059.3 | G13: =IS!G6 -> 16801.09
B14: % of revenue | C14: =C13/C7 -> 0.22534492 | D14: =D13/D7 -> 0.22700969 | E14: =E13/E7 -> 0.22537878 | F14: =F13/F7 -> 0.22231664 | G14: =G13/G7 -> 0.23694163 | H14: =CHOOSE($C$1,H15,H16,H17,) -> 0.22739833 | I14: =CHOOSE($C$1,I15,I16,I17,) -> 0.22739833 | J14: =CHOOSE($C$1,J15,J16,J17,) -> 0.22739833 | K14: =CHOOSE($C$1,K15,K16,K17,) -> 0.22739833 | L14: =CHOOSE($C$1,L15,L16,L17,) -> 0.22739833
B15: Scenario 1 | H15: =H16+5% -> 0.27739833 | I15: =I16+5% -> 0.27739833 | J15: =J16+5% -> 0.27739833 | K15: =K16+5% -> 0.27739833 | L15: =L16+5% -> 0.27739833
B16: Scenario 2 | H16: =AVERAGE(C14:G14) -> 0.22739833 | I16: =H16 -> 0.22739833 | J16: =I16 -> 0.22739833 | K16: =J16 -> 0.22739833 | L16: =K16 -> 0.22739833
B17: Scenario 3 | H17: =H16-5% -> 0.17739833 | I17: =I16-5% -> 0.17739833 | J17: =J16-5% -> 0.17739833 | K17: =K16-5% -> 0.17739833 | L17: =L16-5% -> 0.17739833
B19: Power and Fuel (% of revenue) | C19: =IS!C8/IS!C5 -> 0.20072807 | D19: =IS!D8/IS!D5 -> 0.18627235 | E19: =IS!E8/IS!E5 -> 0.23075152 | F19: =IS!F8/IS!F5 -> 0.29239921 | G19: =IS!G8/IS!G5 -> 0.25784515 | H19: =AVERAGE(C19:G19) -> 0.23359926 | I19: =H19 -> 0.23359926 | J19: =I19 -> 0.23359926 | K19: =J19 -> 0.23359926 | L19: =K19 -> 0.23359926
B20: Employee Cost (growth y-o-y) | D20: =(IS!D9-IS!C9)/IS!C9 -> -0.063152095 | E20: =(IS!E9-IS!D9)/IS!D9 -> 0.076870348 | F20: =(IS!F9-IS!E9)/IS!E9 -> 0.081064833 | G20: =(IS!G9-IS!F9)/IS!F9 -> 0.10928612 | H20: =AVERAGE(E20:G20) -> 0.089073768 | I20: =H20 -> 0.089073768 | J20: =I20 -> 0.089073768 | K20: =J20 -> 0.089073768 | L20: =K20 -> 0.089073768
B21: Selling and admin (growth y-o-y) | D21: =(IS!D10-IS!C10)/IS!C10 -> 0.0025539897 | E21: =(IS!E10-IS!D10)/IS!D10 -> 0.17896293 | F21: =(IS!F10-IS!E10)/IS!E10 -> 0.19404738 | G21: =(IS!G10-IS!F10)/IS!F10 -> 0.13918069 | H21: =AVERAGE(E21:G21) -> 0.17073033 | I21: =H21 -> 0.17073033 | J21: =I21 -> 0.17073033 | K21: =J21 -> 0.17073033 | L21: =K21 -> 0.17073033
B22: Other Expenses (growth y-o-y) | D22: =(IS!D11-IS!C11)/IS!C11 -> -0.22408656 | E22: =(IS!E11-IS!D11)/IS!D11 -> 0.21181417 | F22: =(IS!F11-IS!E11)/IS!E11 -> 0.15273365 | G22: =(IS!G11-IS!F11)/IS!F11 -> 0.19034005 | H22: =AVERAGE(E22:G22) -> 0.18496262 | I22: =H22 -> 0.18496262 | J22: =I22 -> 0.18496262 | K22: =J22 -> 0.18496262 | L22: =K22 -> 0.18496262
B24: Tax Expenses | C24: =IS!C18 -> -568.16 | D24: =IS!D18 -> 2538.7 | E24: =IS!E18 -> 1190.06 | F24: =IS!F18 -> 2342.85 | G24: =IS!G18 -> 2418.26
B25: % of PBT | C25: =C24/IS!C17 -> -0.10962583 | D25: =D24/IS!D17 -> 0.31731568 | E25: =E24/IS!E17 -> 0.13960762 | F25: =F24/IS!F17 -> 0.31590764 | G25: =G24/IS!G17 -> 0.25665501 | H25: =CHOOSE($C$1,H26,H27,H28,) -> 0.25 | I25: =CHOOSE($C$1,I26,I27,I28,) -> 0.25 | J25: =CHOOSE($C$1,J26,J27,J28,) -> 0.25 | K25: =CHOOSE($C$1,K26,K27,K28,) -> 0.25 | L25: =CHOOSE($C$1,L26,L27,L28,) -> 0.25
B26: Scenario 1 | H26: =H27+2% -> 0.27 | I26: =H26 -> 0.27 | J26: =I26 -> 0.27 | K26: =J26 -> 0.27 | L26: =K26 -> 0.27
B27: Scenario 2 | H27: 0.25 | I27: =H27 -> 0.25 | J27: =I27 -> 0.25 | K27: =J27 -> 0.25 | L27: =K27 -> 0.25
B28: Scenario 3 | H28: =H27-2% -> 0.23 | I28: =H28 -> 0.23 | J28: =I28 -> 0.23 | K28: =J28 -> 0.23 | L28: =K28 -> 0.23
B31: Interest Expenses
B32: Short term Borrowings | C32: =BS!C24 -> 4106 | D32: =BS!D24 -> 6939 | E32: =BS!E24 -> 4900 | F32: =BS!F24 -> 4544 | G32: =BS!G24 -> 4991 | H32: =AVERAGE(C32:G32) -> 5096 | I32: =AVERAGE(D32:H32) -> 5294 | J32: =AVERAGE(E32:I32) -> 4965 | K32: =AVERAGE(F32:J32) -> 4978 | L32: =AVERAGE(G32:K32) -> 5064.8
B33: Long term Borrowings | C33: =BS!C27 -> 17368 | D33: =BS!D27 -> 13548 | E33: =BS!E27 -> 5303 | F33: =BS!F27 -> 5356 | G33: =BS!G27 -> 5308 | H33: =AVERAGE(E33:G33) -> 5322.3333 | I33: =AVERAGE(F33:H33) -> 5328.7778 | J33: =AVERAGE(G33:I33) -> 5319.7037 | K33: =AVERAGE(H33:J33) -> 5323.6049 | L33: =AVERAGE(I33:K33) -> 5324.0288
B34: Interest | C34: =IS!C16 -> 1991.65 | D34: =IS!D16 -> 1485.65 | E34: =IS!E16 -> 944.71 | F34: =IS!F16 -> 822.72 | G34: =IS!G16 -> 968 | H34: =SUM(H32:H33)*H37 -> 906.28643 | I34: =SUM(I32:I33)*I37 -> 911.83891 | J34: =SUM(J32:J33)*J37 -> 910.22054 | K34: =SUM(K32:K33)*K37 -> 903.29162 | L34: =SUM(L32:L33)*L37 -> 920.45913
B37: Interest rate | C37: =C34/SUM(C32:C33) -> 0.092747043 | D37: =D34/SUM(D32:D33) -> 0.072516718 | E37: =E34/SUM(E32:E33) -> 0.092591395 | F37: =F34/SUM(F32:F33) -> 0.08310303 | G37: =G34/SUM(G32:G33) -> 0.093989708 | H37: =AVERAGE(C37:G37) -> 0.086989579 | I37: =AVERAGE(D37:H37) -> 0.085838086 | J37: =AVERAGE(E37:I37) -> 0.088502359 | K37: =AVERAGE(F37:J37) -> 0.087684552 | L37: =AVERAGE(G37:K37) -> 0.088600857
B40: Dividend Paid
B41: Net income | C41: =IS!C19 -> 5750.88 | D41: =IS!D19 -> 5461.85 | E41: =IS!E19 -> 7334.26 | F41: =IS!F19 -> 5073.4 | G41: =IS!G19 -> 7003.96 | H41: =IS!H19 -> 10691.038 | I41: =IS!I19 -> 12884.871 | J41: =IS!J19 -> 15022.942 | ... L41: =IS!L19 -> 18706.819
B42: Dividend Paid | C42: =IS!C20 -> 375.22 | D42: =IS!D20 -> 1068 | E42: =IS!E20 -> 1096.95 | F42: =IS!F20 -> 1097.02 | G42: =IS!G20 -> 2020.83 | H42: =H41*H43 -> 2271.471 | I42: =I41*I43 -> 2792.1087 | J42: =J41*J43 -> 3507.5495 | K42: =K41*K43 -> 4044.3862 | L42: =L41*L43 -> 4211.06
B43: dividend payout ratio (%) | C43: =C42/C41 -> 0.065245667 | D43: =D42/D41 -> 0.19553814 | E43: =E42/E41 -> 0.14956519 | F43: =F42/F41 -> 0.21622975 | G43: =G42/G41 -> 0.28852678 | H43: =AVERAGE(D43:G43) -> 0.21246496 | I43: =AVERAGE(E43:H43) -> 0.21669667 | J43: =AVERAGE(F43:I43) -> 0.23347954 | K43: =AVERAGE(G43:J43) -> 0.23779199 | L43: =AVERAGE(H43:K43) -> 0.22510829
B47: Balance Sheet Drivers
B49: Working Capital
B50: Inventories (% of COGS) | C50: =BS!C5/Drivers!C57 -> 0.43749006 | D50: =BS!D5/Drivers!D57 -> 0.39573769 | E50: =BS!E5/Drivers!E57 -> 0.47205065 | F50: =BS!F5/Drivers!F57 -> 0.47029368 | G50: =BS!G5/Drivers!G57 -> 0.49580117 | H50: =AVERAGE(C50:G50) -> 0.45427465 | I50: =H50 -> 0.45427465 | J50: =I50 -> 0.45427465 | K50: =J50 -> 0.45427465 | L50: =K50 -> 0.45427465
B51: Trade receivables (% of revenue) | C51: =BS!C6/Drivers!C56 -> 0.056163238 | D51: =BS!D6/Drivers!D56 -> 0.057505959 | E51: =BS!E6/Drivers!E56 -> 0.058404341 | F51: =BS!F6/Drivers!F56 -> 0.061148027 | G51: =BS!G6/Drivers!G56 -> 0.060331578 | H51: =AVERAGE(C51:G51) -> 0.058710628 | I51: =H51 -> 0.058710628 | J51: =I51 -> 0.058710628 | K51: =J51 -> 0.058710628 | L51: =K51 -> 0.058710628
B52: Loans n Advances (% of revenue) | C52: =BS!C8/Drivers!C56 -> 0.01876036 | D52: =BS!D8/Drivers!D56 -> 0.014756583 | E52: =BS!E8/Drivers!E56 -> 0.016597327 | F52: =BS!F8/Drivers!F56 -> 0.015037955 | G52: =BS!G8/Drivers!G56 -> 0.013891212 | H52: =AVERAGE(C52:G52) -> 0.015808688 | I52: =H52 -> 0.015808688 | J52: =I52 -> 0.015808688 | K52: =J52 -> 0.015808688 | L52: =K52 -> 0.015808688
B53: Trade Payables (% of COGS) | C53: =BS!C21/Drivers!C57 -> 0.35172821 | D53: =BS!D21/Drivers!D57 -> 0.44793804 | E53: =BS!E21/Drivers!E57 -> 0.49457344 | F53: =BS!F21/Drivers!F57 -> 0.51275668 | G53: =BS!G21/Drivers!G57 -> 0.50461012 | H53: =AVERAGE(C53:G53) -> 0.4623213 | I53: =H53 -> 0.4623213 | J53: =I53 -> 0.4623213 | K53: =J53 -> 0.4623213 | L53: =K53 -> 0.4623213
B54: Advance from Customers (% of revenue) | C54: =BS!C22/Drivers!C56 -> 0.010935687 | D54: =BS!D22/Drivers!D56 -> 0.0092787608 | E54: =BS!E22/Drivers!E56 -> 0.0088405008 | F54: =BS!F22/Drivers!F56 -> 0.0060721082 | G54: =BS!G22/Drivers!G56 -> 0.0074321509 | H54: =AVERAGE(C54:G54) -> 0.0085118416 | I54: =H54 -> 0.0085118416 | J54: =I54 -> 0.0085118416 | K54: =J54 -> 0.0085118416 | L54: =K54 -> 0.0085118416
...

Sheet Source>

Sheet (IS)
A1: PROFIT & LOSS | L1: Index
A2: Report Date | B2: 42460 | C2: 42825 | D2: 43190 | E2: 43555 | F2: 43921 | G2: 44286 | H2: 44651 | I2: 45016 | J2: 45382 | K2: 45747
A3: Sales | B3: 25153.24 | C3: 25374.94 | D3: 30978.62 | E3: 41462.26 | F3: 42429.89 | G3: 44725.8 | H3: 52598.83 | I3: 63239.98 | J3: 70908.14 | K3: 75955.13
A4: Raw Material Cost | B4: 4436.12 | C4: 4416.9 | D4: 5399.98 | E4: 6936.74 | F4: 6875.89 | G4: 6635.66 | H4: 8348.15 | I4: 10233.17 | J4: 11986.27 | K4: 13691.46
A5: Change in Inventory | B5: 18.61 | C5: -75.69 | D5: 111.2 | E5: -46.35 | F5: 357.83 | G5: -450.15 | H5: 383.16 | I5: 518.21 | J5: 83.35 | K5: -12.27 | M5: =G4-G5+G7 -> 10153.19 | N5: 450
A6: Power and Fuel | B6: 4579.25 | C6: 4271.98 | D6: 6334.07 | E6: 9436.14 | F6: 8516.87 | G6: 8331.18 | H6: 12137.26 | I6: 18491.32 | J6: 18283.32 | K6: 18419.15 | N6: =G4-N5+G7 -> 9253.04
A7: Other Mfr. Exp | B7: 1933.88 | C7: 1991.28 | D7: 2289.53 | E7: 3001.06 | F7: 3043.3 | G7: 3067.38 | H7: 3889.67 | I7: 4344.34 | J7: 4898.17 | K7: 5474.61
A8: Employee Cost | B8: 1466.49 | C8: 1547.77 | D8: 1831.81 | E8: 2309.43 | F8: 2522.64 | G8: 2363.33 | H8: 2545 | I8: 2751.31 | J8: 3051.99 | K8: 3619.25
A9: Selling and admin | B9: 7200.47 | C9: 7149.12 | D9: 8320.28 | E9: 11563.8 | F9: 11237.32 | G9: 11266.02 | H9: 13282.22 | I9: 15859.6 | J9: 18066.95 | K9: 19571.95
A10: Other Expenses | B10: 654.67 | C10: 709.76 | D10: 769.12 | E10: 821.8 | F10: 1345.73 | G10: 1044.17 | H10: 1265.34 | I10: 1458.6 | J10: 1736.23 | K10: 2369.56
A11: Other Income | B11: 463.81 | C11: 648.12 | D11: 241.97 | E11: 350.1 | F11: 651.06 | G11: 618.52 | H11: 669.43 | I11: 507.11 | J11: 566.96 | K11: 396.74
A12: Depreciation | B12: 1377.17 | C12: 1348.41 | D12: 1847.93 | E12: 2450.73 | F12: 2722.66 | G12: 2700.23 | H12: 2714.75 | I12: 2887.99 | J12: 3145.3 | K12: 4014.95
A13: Interest | B13: 566.3 | C13: 640.1 | D13: 1237.6 | E13: 1777.86 | F13: 1991.65 | G13: 1485.65 | H13: 944.71 | I13: 822.72 | J13: 968 | K13: 1650.54
A14: Profit before tax | B14: 3421.31 | C14: 3872.05 | D14: 3301.47 | E14: 3468.45 | F14: 5182.72 | G14: 8000.55 | H14: 8524.32 | I14: 7416.25 | J14: 9422.22 | K14: 7528.13
A15: Tax | B15: 941.69 | C15: 1158.54 | D15: 1077.01 | E15: 1068.07 | F15: -568.16 | G15: 2538.7 | H15: 1190.06 | I15: 2342.85 | J15: 2418.26 | K15: 1488.49
A16: Net profit | B16: 2478.04 | C16: 2714.92 | D16: 2222.17 | E16: 2403.51 | F16: 5755.26 | G16: 5463.1 | H16: 7344.31 | I16: 5063.96 | J16: 7005 | K16: 6039.11
A17: Dividend Amount | B17: 260.71 | C17: 274.51 | D17: 288.34 | E17: 315.84 | F17: 375.22 | G17: 1068 | H17: 1096.95 | I17: 1097.02 | J17: 2020.83 | K17: 2283.77
A18: Reserves | B18: =B16-B17 -> 2217.33 | C18: =C16-C17 -> 2440.41 | D18: =D16-D17 -> 1933.83 | E18: =E16-E17 -> 2087.67 | F18: =F16-F17 -> 5380.04 | G18: =G16-G17 -> 4395.1 | H18: =H16-H17 -> 6247.36 | I18: =I16-I17 -> 3966.94 | ... K18: =K16-K17 -> 3755.34
G22: Weightage | H22: Year | I22: Sales | J22: Growth
G23: 1 | H23: 42460 | I23: 25153.24
G24: 2 | H24: 42825 | I24: 25374.94 | J24: =(I24-I23)/I23 -> 0.0088139739
G25: 3 | H25: 43190 | I25: 30978.62 | J25: =(I25-I24)/I24 -> 0.2208352
G26: 4 | H26: 43555 | I26: 41462.26 | J26: =(I26-I25)/I25 -> 0.33841533
G27: 5 | H27: 43921 | I27: 42429.89 | J27: =(I27-I26)/I26 -> 0.023337609
G28: 6 | H28: 44286 | I28: 44725.8 | J28: =(I28-I27)/I27 -> 0.054110675
G29: 7 | H29: 44651 | I29: 52598.83 | J29: =(I29-I28)/I28 -> 0.17602882
G30: 8 | H30: 45016 | I30: 63239.98 | J30: =(I30-I29)/I29 -> 0.20230773
G31: 9 | H31: 45382 | I31: 70908.14 | J31: =(I31-I30)/I30 -> 0.12125494
G32: 10 | H32: 45747 | I32: 75955.13 | J32: =(I32-I31)/I31 -> 0.071176454
G33: 11
G34: 12
H36: Arithmetic Mean | J36: =AVERAGE(J24:J32) -> 0.1351423
H37: Geometric Mean | J37: =(I32/I23)^(1/9)-1 -> 0.13065275 | K37: =_xlfn.RRI(9,I23,I32) -> 0.13065275
H38: Regression | J38: =FORECAST(G33,J23:J32,G23:G32) -> 0.1210744 | K38: 0.167

Sheet (BS)
A1: Balance Sheet | P1: Index
B2: 41699 | C2: 42064 | D2: 42430 | E2: 42795 | F2: 43160 | G2: 43525 | H2: 43891 | I2: 44256 | J2: 44621 | K2: 44986 | L2: 45352 | M2: 45717
A3: Equity Capital | B3: 274 | C3: 274 | D3: 274 | E3: 275 | F3: 275 | G3: 275 | H3: 289 | I3: 289 | J3: 289 | K3: 289 | L3: 289 | M3: 295 | O3: L
A4: Reserves | B4: 16908 | C4: 18767 | D4: 21671 | E4: 24117 | F4: 26107 | G4: 33476 | H4: 38755 | I4: 43886 | J4: 50147 | K4: 54036 | L4: 59939 | M4: 70412 | O4: L
A5: Borrowings - | B5: 7332 | C5: 9829 | D5: 10616 | E5: 8474 | F5: 19480 | G5: 25337 | H5: 23019 | I5: 21719 | J5: 11299 | K5: 11058 | L5: 11403 | M5: 24102
A6: Long term Borrowings | B6: 6021 | C6: 4993 | D6: 4897 | E6: 6371 | F6: 15863 | G6: 20650 | H6: 17368 | I6: 13548 | J6: 5303 | K6: 5356 | L6: 5308 | M6: 15781 | O6: NCL
A7: Short term Borrowings | B7: 985 | C7: 2564 | D7: 2476 | E7: 1079 | F7: 2763 | G7: 3668 | H7: 4106 | I7: 6939 | J7: 4900 | K7: 4544 | L7: 4991 | M7: 7250 | O7: CL
A8: Lease Liabilities | B8: 0 | C8: 0 | D8: 0 | E8: 0 | F8: 0 | G8: 0 | H8: 0 | I8: 1232 | J8: 1096 | K8: 1157 | L8: 1103 | M8: 1070 | O8: NCL
A9: Other Borrowings | B9: 327 | C9: 2273 | D9: 3244 | E9: 1024 | F9: 853 | G9: 1018 | H9: 1545 | I9: 0 | J9: 0 | K9: 0 | L9: 0 | M9: 0 | O9: NCL
A10: Other Liabilities - | B10: 7671 | C10: 9183 | D10: 8631 | E10: 9343 | F10: 11280 | G10: 17438 | H10: 17151 | I10: 20282 | J10: 22077 | K10: 25998 | L10: 29167 | M10: 38823
A11: Non controlling int | B11: 17 | C11: 18 | D11: 15 | E11: 10 | F11: 16 | G11: 12 | H11: 10 | I11: 6 | J11: -3 | K11: 55 | L11: 56 | M11: 3187 | O11: L
A12: Trade Payables | B12: 2591 | C12: 1711 | D12: 1717 | E12: 1849 | F12: 2385 | G12: 3160 | H12: 3363 | I12: 4548 | J12: 5863 | K12: 7209 | L12: 8478 | M12: 9327 | O12: CL
A13: Advance from Customers | B13: 0 | C13: 0 | D13: 166 | E13: 196 | F13: 305 | G13: 357 | H13: 464 | I13: 415 | J13: 465 | K13: 384 | L13: 527 | M13: 541 | O13: CL | P13: =I5+I10 -> 42001
A14: Other liability items | B14: 5063 | C14: 7454 | D14: 6733 | E14: 7288 | F14: 8574 | G14: 13909 | H14: 13316 | I14: 15313 | J14: 15753 | K14: 18349 | L14: 20106 | M14: 25768 | O14: CL
A15: Total Liabilities | B15: 32185 | C15: 38053 | D15: 41193 | E15: 42209 | F15: 57141 | G15: 76525 | H15: 79214 | I15: 86176 | J15: 83811 | K15: 91380 | L15: 100797 | M15: 133632 | O15: TL
A16: Fixed Assets - | B16: 18100 | C16: 23343 | D16: 25309 | E16: 25904 | F16: 39715 | G16: 56645 | H16: 57151 | I16: 55412 | J16: 55488 | K16: 59579 | L16: 62878 | M16: 94564
A17: Land | B17: 2154 | C17: 3311 | D17: 3627 | E17: 3785 | F17: 6361 | G17: 7492 | H17: 7943 | I17: 8085 | J17: 8454 | K17: 8709 | L17: 9259 | M17: 19872 | O17: NCA
A18: Building | B18: 2059 | C18: 2792 | D18: 2469 | E18: 2766 | F18: 4346 | G18: 5130 | H18: 5511 | I18: 5606 | J18: 5831 | K18: 6287 | L18: 6772 | M18: 9361
A19: Plant Machinery | B19: 21482 | C19: 26327 | D19: 18452 | E19: 19713 | F19: 28048 | G19: 36920 | H19: 38369 | I19: 38655 | J19: 40604 | K19: 46270 | L19: 51343 | M19: 67010
A20: Ships Vessels | B20: 0 | C20: 0 | D20: 0 | E20: 0 | F20: 0 | G20: 0 | H20: 717 | I20: 830 | J20: 719 | K20: 793 | L20: 801 | M20: 792
A21: Equipments | B21: 214 | C21: 236 | D21: 99 | E21: 115 | F21: 150 | G21: 208 | H21: 265 | I21: 289 | J21: 336 | K21: 387 | L21: 466 | M21: 555
A22: Furniture n fittings | B22: 146 | C22: 163 | D22: 57 | E22: 71 | F22: 80 | G22: 106 | H22: 112 | I22: 111 | J22: 114 | K22: 122 | L22: 154 | M22: 219
A23: Railway sidings | B23: 492 | C23: 536 | D23: 399 | E23: 444 | F23: 653 | G23: 890 | H23: 906 | I23: 959 | J23: 989 | K23: 1008 | L23: 1088 | M23: 1305
A24: Vehicles | B24: 65 | C24: 78 | D24: 46 | E24: 63 | F24: 91 | G24: 110 | H24: 122 | I24: 133 | J24: 163 | K24: 200 | L24: 260 | M24: 354
A25: Intangible Assets | B25: 967 | C25: 1053 | D25: 1287 | E25: 1329 | F25: 1280 | G25: 6626 | H25: 6680 | I25: 6375 | J25: 6405 | K25: 6484 | L25: 6501 | M25: 8108 | O25: NCA
A26: Other fixed assets | B26: 275 | C26: 414 | D26: 176 | E26: 213 | F26: 3073 | G26: 5899 | H26: 5927 | I26: 6289 | J26: 6387 | K26: 6695 | L26: 6637 | M26: 11055 | O26: NCA
A27: Gross Block | B27: 27854 | C27: 34910 | D27: 26611 | E27: 28498 | F27: 44082 | G27: 63382 | H27: 66550 | I27: 67332 | J27: 70002 | K27: 76957 | L27: 83280 | M27: 118631
A28: Accumulated Depreciation | B28: 9754 | C28: 11567 | D28: 1302 | E28: 2594 | F28: 4366 | G28: 6737 | H28: 9399 | I28: 11921 | J28: 14514 | K28: 17378 | L28: 20403 | M28: 24067 | O28: NCA
A29: CWIP | B29: 2186 | C29: 2250 | D29: 1469 | E29: 921 | F29: 1511 | G29: 1153 | H29: 920 | I29: 1687 | J29: 4785 | K29: 4040 | L29: 6811 | M29: 6234 | O29: NCA
A30: Investments | B30: 4862 | C30: 4500 | D30: 5095 | E30: 6691 | F30: 5447 | G30: 2921 | H30: 5929 | I30: 12178 | J30: 6336 | K30: 7297 | L30: 8249 | M30: 5156 | O30: NCA
A31: Other Assets - | B31: 7037 | C31: 7961 | D31: 9319 | E31: 8693 | F31: 10468 | G31: 15806 | H31: 15215 | I31: 16900 | J31: 17203 | K31: 20464 | L31: 22859 | M31: 27677
A32: Inventories | B32: 2580 | C32: 2949 | D32: 2455 | E32: 2401 | F32: 3268 | G32: 4099 | H32: 4183 | I32: 4018 | J32: 5596 | K32: 6612 | L32: 8330 | M32: 9563 | O32: CA
A33: Trade receivables - | B33: 1632 | C33: 1659 | D33: 1928 | E33: 1757 | F33: 2221 | G33: 2787 | H33: 2383 | I33: 2572 | J33: 3072 | K33: 3867 | L33: 4278 | M33: 5890 | O33: CA
A34: Cash Equivalents | B34: 348 | C34: 371 | D34: 2267 | E34: 2249 | F34: 219 | G34: 740 | H34: 540 | I34: 2008 | J34: 359 | K34: 1150 | L34: 783 | M34: 1673 | O34: CA
A35: Loans n Advances | B35: 145 | C35: 2 | D35: 377 | E35: 519 | F35: 544 | G35: 750 | H35: 796 | I35: 660 | J35: 873 | K35: 951 | L35: 985 | M35: 1259 | O35: CA
A36: Other asset items | B36: 2331 | C36: 2980 | D36: 2292 | E36: 1768 | F36: 4216 | G36: 7430 | H36: 7312 | I36: 7642 | J36: 7304 | K36: 7885 | L36: 8483 | M36: 9292 | O36: CA
A37: Total Assets | B37: 32185 | C37: 38053 | D37: 41193 | E37: 42209 | F37: 57141 | G37: 76525 | H37: 79214 | I37: 86176 | J37: 83811 | K37: 91380 | L37: 100797 | M37: 133632

Sheet (CFS)
A1: Cash Flows | N1: Index
B2: 41699 | C2: 42064 | D2: 42430 | E2: 42795 | F2: 43160 | G2: 43525 | H2: 43891 | I2: 44256 | J2: 44621 | K2: 44986 | L2: 45352 | M2: 45717
A3: Cash from Operating Activity - | B3: 3455 | C3: 4190 | D3: 4526 | E3: 5005 | F3: 3888 | G3: 5956 | H3: 8972 | I3: 12500 | J3: 9283 | K3: 9069 | L3: 10898 | M3: 10673
A4: Profit from operations | B4: 4052 | C4: 4464 | D4: 4948 | E4: 5220 | F4: 5986 | G4: 7362 | H4: 9348 | I4: 11465 | J4: 11311 | K4: 10530 | L4: 13029 | M4: 12645
A5: Receivables | B5: -256 | C5: -27 | D5: -287 | E5: 156 | F5: -454 | G5: -279 | H5: 473 | I5: -201 | J5: -495 | K5: -752 | L5: -421 | M5: -608
A6: Inventory | B6: -40 | C6: -326 | D6: 374 | E6: 54 | F6: -623 | G6: -15 | H6: -64 | I6: 165 | J6: -1579 | K6: -992 | L6: -1712 | M6: -317
A7: Payables | B7: 444 | C7: 383 | D7: 310 | E7: 482 | F7: 346 | G7: 766 | H7: 279 | I7: 2868 | J7: 2077 | K7: 1869 | L7: 1959 | M7: -476
A8: Loans Advances | B8: -73 | C8: -135 | D8: 0 | E8: 0 | F8: 0 | G8: 0 | H8: 0 | I8: 0 | J8: 0 | K8: 0 | L8: 0 | M8: 0
A9: Other WC items | B9: 0 | C9: 0 | D9: 32 | E9: -162 | F9: -525 | G9: -1167 | H9: -172 | I9: -505 | J9: -476 | K9: -461 | L9: -308 | M9: 729
A10: Working capital changes | B10: 76 | C10: -104 | D10: 429 | E10: 529 | F10: -1255 | G10: -696 | H10: 516 | I10: 2326 | J10: -473 | K10: -337 | L10: -481 | M10: -671
A11: Direct taxes | B11: -669 | C11: -169 | D11: -852 | E11: -744 | F11: -843 | G11: -710 | H11: -891 | I11: -1291 | J11: -1555 | K11: -1124 | L11: -1651 | M11: -1301
A12: Other operating items | B12: -3 | C12: 0 | D12: 0 | E12: 0 | F12: 0 | G12: 0 | H12: 0 | I12: 0 | J12: 0 | K12: 0 | L12: 0 | M12: 0
A13: Cash from Investing Activity - | B13: -2342 | C13: -2144 | D13: -3673 | E13: -2501 | F13: 1866 | G13: 1165 | H13: -4192 | I13: -8856 | J13: 2257 | K13: -7188 | L13: -8789 | M13: -15836
A14: Fixed assets purchased | B14: -2314 | C14: -2722 | D14: -2150 | E14: -1402 | F14: -2103 | G14: -1808 | H14: -1766 | I14: -1925 | J14: -5613 | K14: -6200 | L14: -9006 | M14: -9129
... A33: Net Cash Flow | B33: 164 | C33: -63 | D33: 8 | E33: -31 | F33: 18 | G33: 364 | H33: -295 | I33: -712 | J33: -958 | K33: 250 | L33: 183 | M33: -86

Sheet 3 Statment Model

Sheet IS
B2: Income Statement | K2: Index
B3: All figures in Rs.Crores
B4: Financial Year | C4: 43891 | D4: 44256 | E4: 44621 | F4: 44986 | G4: 45352 | H4: 45717 | I4: 46082 | J4: 46447 | K4: 46813 | L4: 47178
B5: Total Revenue | C5: ='(IS)'!F3 -> 42429.89 | D5: ='(IS)'!G3 -> 44725.8 | E5: ='(IS)'!H3 -> 52598.83 | F5: ='(IS)'!I3 -> 63239.98 | G5: ='(IS)'!J3 -> 70908.14 | H5: =G5*(1+Drivers!H8) -> 82749.799 | I5: =H5*(1+Drivers!I8) -> 96569.016 | J5: =I5*(1+Drivers!J8) -> 111730.35 | K5: =J5*(1+Drivers!K8) -> 128154.71 | L5: =K5*(1+Drivers!L8) -> 145711.91
B6: COGS | C6: ='(IS)'!F4-'(IS)'!F5+'(IS)'!F7 -> 9561.36 | D6: ='(IS)'!G4-'(IS)'!G5+'(IS)'!G7 -> 10153.19 | E6: ='(IS)'!H4-'(IS)'!H5+'(IS)'!H7 -> 11854.66 | F6: ='(IS)'!I4-'(IS)'!I5+'(IS)'!I7 -> 14059.3 | G6: ='(IS)'!J4-'(IS)'!J5+'(IS)'!J7 -> 16801.09 | H6: =H5*Drivers!H14 -> 18817.166 | I6: =I5*Drivers!I14 -> 21959.633 | J6: =J5*Drivers!J14 -> 25407.295 | K6: =K5*Drivers!K14 -> 29142.168 | L6: =L5*Drivers!L14 -> 33134.645
B7: Gross Profit | C7: =C5-C6 -> 32868.53 | D7: =D5-D6 -> 34572.61 | E7: =E5-E6 -> 40744.17 | F7: =F5-F6 -> 49180.68 | G7: =G5-G6 -> 54107.05 | H7: =H5-H6 -> 63932.633 | I7: =I5-I6 -> 74609.383 | J7: =J5-J6 -> 86323.056 | ... L7: =L5-L6 -> 112577.26
B8: Power and Fuel | C8: ='(IS)'!F6 -> 8516.87 | D8: ='(IS)'!G6 -> 8331.18 | E8: ='(IS)'!H6 -> 12137.26 | F8: ='(IS)'!I6 -> 18491.32 | G8: ='(IS)'!J6 -> 18283.32 | H8: =H5*Drivers!H19 -> 19330.292 | I8: =I5*Drivers!I19 -> 22558.451 | J8: =J5*Drivers!J19 -> 26100.127 | K8: =K5*Drivers!K19 -> 29936.846 | L8: =L5*Drivers!L19 -> 34038.194
B9: Employee Cost | C9: ='(IS)'!F8 -> 2522.64 | D9: ='(IS)'!G8 -> 2363.33 | E9: ='(IS)'!H8 -> 2545 | F9: ='(IS)'!I8 -> 2751.31 | G9: ='(IS)'!J8 -> 3051.99 | H9: =G9*(1+Drivers!H20) -> 3323.8422 | I9: =H9*(1+Drivers!I20) -> 3619.9094 | J9: =I9*(1+Drivers!J20) -> 3942.3484 | K9: =J9*(1+Drivers!K20) -> 4293.5082 | L9: =K9*(1+Drivers!L20) -> 4675.9471
B10: Selling and admin | C10: ='(IS)'!F9 -> 11237.32 | D10: ='(IS)'!G9 -> 11266.02 | E10: ='(IS)'!H9 -> 13282.22 | F10: ='(IS)'!I9 -> 15859.6 | G10: ='(IS)'!J9 -> 18066.95 | H10: =G10*(1+Drivers!H21) -> 21151.526 | I10: =H10*(1+Drivers!I21) -> 24762.734 | J10: =I10*(1+Drivers!J21) -> 28990.483 | K10: =J10*(1+Drivers!K21) -> 33940.038 | L10: =K10*(1+Drivers!L21) -> 39734.632
B11: Other Expenses | C11: ='(IS)'!F10 -> 1345.73 | D11: ='(IS)'!G10 -> 1044.17 | E11: ='(IS)'!H10 -> 1265.34 | F11: ='(IS)'!I10 -> 1458.6 | G11: ='(IS)'!J10 -> 1736.23 | H11: =G11*(1+Drivers!H22) -> 2057.3677 | I11: =H11*(1+Drivers!I22) -> 2437.9038 | J11: =I11*(1+Drivers!J22) -> 2888.8249 | K11: =J11*(1+Drivers!K22) -> 3423.1495 | L11: =K11*(1+Drivers!L22) -> 4056.3042
B12: Other Income | C12: ='(IS)'!F11 -> 651.06 | D12: ='(IS)'!G11 -> 618.52 | E12: ='(IS)'!H11 -> 669.43 | F12: ='(IS)'!I11 -> 507.11 | G12: ='(IS)'!J11 -> 566.96 | H12: =AVERAGE(C12:G12) -> 602.616 | I12: =AVERAGE(D12:H12) -> 592.9272 | J12: =AVERAGE(E12:I12) -> 587.80864 | K12: =AVERAGE(F12:J12) -> 571.48437 | L12: =AVERAGE(G12:K12) -> 584.35924
B13: EBIDTA | C13: =C7-C8-C9-C10-C11+C12 -> 9897.03 | D13: =D7-D8-D9-D10-D11+D12 -> 12186.43 | E13: =E7-E8-E9-E10-E11+E12 -> 12183.78 | F13: =F7-F8-F9-F10-F11+F12 -> 11126.96 | G13: =G7-G8-G9-G10-G11+G12 -> 13535.52 | H13: =H7-H8-H9-H10-H11+H12 -> 18672.221 | I13: =I7-I8-I9-I10-I11+I12 -> 21823.313 | J13: =J7-J8-J9-J10-J11+J12 -> 24989.081 | ... L13: =L7-L8-L9-L10-L11+L12 -> 30656.545
A14: O | B14: Depreciation and Amortization | C14: ='(IS)'!F12 -> 2722.66 | D14: ='(IS)'!G12 -> 2700.23 | E14: ='(IS)'!H12 -> 2714.75 | F14: ='(IS)'!I12 -> 2887.99 | G14: ='(IS)'!J12 -> 3145.3 | H14: =PPE!H16 -> 3511.2171 | I14: =PPE!I16 -> 3731.6454 | J14: =PPE!J16 -> 4048.271 | K14: =PPE!K16 -> 4409.7501 | L14: =PPE!L16 -> 4793.6613
B15: EBIT | C15: =C13-C14 -> 7174.37 | D15: =D13-D14 -> 9486.2 | E15: =E13-E14 -> 9469.03 | F15: =F13-F14 -> 8238.97 | G15: =G13-G14 -> 10390.22 | H15: =H13-H14 -> 15161.004 | I15: =I13-I14 -> 18091.667 | J15: =J13-J14 -> 20940.81 | ... L15: =L13-L14 -> 25862.884
B16: Interest | C16: ='(IS)'!F13 -> 1991.65 | D16: ='(IS)'!G13 -> 1485.65 | E16: ='(IS)'!H13 -> 944.71 | F16: ='(IS)'!I13 -> 822.72 | G16: ='(IS)'!J13 -> 968 | H16: =Drivers!H34 -> 906.28643 | I16: =Drivers!I34 -> 911.83891 | J16: =Drivers!J34 -> 910.22054 | K16: =Drivers!K34 -> 903.29162 | L16: =Drivers!L34 -> 920.45913
B17: EBT | C17: =C15-C16 -> 5182.72 | D17: =D15-D16 -> 8000.55 | E17: =E15-E16 -> 8524.32 | F17: =F15-F16 -> 7416.25 | G17: =G15-G16 -> 9422.22 | H17: =H15-H16 -> 14254.717 | I17: =I15-I16 -> 17179.828 | J17: =J15-J16 -> 20030.589 | ... L17: =L15-L16 -> 24942.425
B18: Taxes | C18: ='(IS)'!F15 -> -568.16 | D18: ='(IS)'!G15 -> 2538.7 | E18: ='(IS)'!H15 -> 1190.06 | F18: ='(IS)'!I15 -> 2342.85 | G18: ='(IS)'!J15 -> 2418.26 | H18: =H17*Drivers!H25 -> 3563.6793 | I18: =I17*Drivers!I25 -> 4294.9571 | J18: =J17*Drivers!J25 -> 5007.6473 | K18: =K17*Drivers!K25 -> 5669.3615 | L18: =L17*Drivers!L25 -> 6235.6063
A19: O | B19: EAT/Net Profit | C19: =C17-C18 -> 5750.88 | D19: =D17-D18 -> 5461.85 | E19: =E17-E18 -> 7334.26 | F19: =F17-F18 -> 5073.4 | G19: =G17-G18 -> 7003.96 | H19: =H17-H18 -> 10691.038 | I19: =I17-I18 -> 12884.871 | J19: =J17-J18 -> 15022.942 | ... L19: =L17-L18 -> 18706.819
A20: F | B20: Dividend Paid | C20: ='(IS)'!F17 -> 375.22 | D20: ='(IS)'!G17 -> 1068 | E20: ='(IS)'!H17 -> 1096.95 | F20: ='(IS)'!I17 -> 1097.02 | G20: ='(IS)'!J17 -> 2020.83 | H20: =Drivers!H42 -> 2271.471 | I20: =Drivers!I42 -> 2792.1087 | J20: =Drivers!J42 -> 3507.5495 | K20: =Drivers!K42 -> 4044.3862 | L20: =Drivers!L42 -> 4211.06
B21: Transfer to Reserve | C21: =C19-C20 -> 5375.66 | D21: =D19-D20 -> 4393.85 | E21: =E19-E20 -> 6237.31 | F21: =F19-F20 -> 3976.38 | G21: =G19-G20 -> 4983.13 | H21: =H19-H20 -> 8419.567 | I21: =I19-I20 -> 10092.763 | J21: =J19-J20 -> 11515.392 | ... L21: =L19-L20 -> 14495.759

Sheet BS
B2: Balance Sheet | L2: Index
B3: All figures in Rs.Crores
B4: Financial Year | C4: 43891 | D4: 44256 | E4: 44621 | F4: 44986 | G4: 45352 | H4: 45717 | I4: 46082 | J4: 46447 | K4: 46813 | L4: 47178
A5: O | B5: Inventories | C5: ='(BS)'!H32 -> 4183 | D5: ='(BS)'!I32 -> 4018 | E5: ='(BS)'!J32 -> 5596 | F5: ='(BS)'!K32 -> 6612 | G5: ='(BS)'!L32 -> 8330 | H5: =WC!H5 -> 8548.1616 | I5: =WC!I5 -> 9975.7046 | J5: =WC!J5 -> 11541.89 | K5: =WC!K5 -> 13238.548 | L5: =WC!L5 -> 15052.229
A6: O | B6: Trade receivables | C6: ='(BS)'!H33 -> 2383 | D6: ='(BS)'!I33 -> 2572 | E6: ='(BS)'!J33 -> 3072 | F6: ='(BS)'!K33 -> 3867 | G6: ='(BS)'!L33 -> 4278 | H6: =WC!H6 -> 4858.2927 | I6: =WC!I6 -> 5669.6276 | J6: =WC!J6 -> 6559.7592 | K6: =WC!K6 -> 7524.0437 | L6: =WC!L6 -> 8554.8377
B7: Cash Equivalents | C7: ='(BS)'!H34 -> 540 | D7: ='(BS)'!I34 -> 2008 | E7: ='(BS)'!J34 -> 359 | F7: ='(BS)'!K34 -> 1150 | G7: ='(BS)'!L34 -> 783 | H7: =G7+CFS!H30 -> 4637.1043 | I7: =H7+CFS!I30 -> 7815.4311 | J7: =I7+CFS!J30 -> 10624.986 | K7: =J7+CFS!K30 -> 14964.086 | L7: =K7+CFS!L30 -> 20652.414
A8: F | B8: Loans n Advances | C8: ='(BS)'!H35 -> 796 | D8: ='(BS)'!I35 -> 660 | E8: ='(BS)'!J35 -> 873 | F8: ='(BS)'!K35 -> 951 | G8: ='(BS)'!L35 -> 985 | H8: =WC!H7 -> 1308.1657 | I8: =WC!I7 -> 1526.6294 | J8: =WC!J7 -> 1766.3102 | K8: =WC!K7 -> 2025.9578 | L8: =WC!L7 -> 2303.514
A9: O | B9: Other asset items | C9: ='(BS)'!H36 -> 7312 | D9: ='(BS)'!I36 -> 7642 | E9: ='(BS)'!J36 -> 7304 | F9: ='(BS)'!K36 -> 7885 | G9: ='(BS)'!L36 -> 8483 | H9: =WC!H8 -> 7725.2 | I9: =WC!I8 -> 7807.84 | J9: =WC!J8 -> 7841.008 | K9: =WC!K8 -> 7948.4096 | L9: =WC!L8 -> 7961.0915
B10: Current Assets | C10: =SUM(C5:C9) -> 15214 | D10: =SUM(D5:D9) -> 16900 | E10: =SUM(E5:E9) -> 17204 | F10: =SUM(F5:F9) -> 20465 | G10: =SUM(G5:G9) -> 22859 | H10: =SUM(H5:H9) -> 27076.924 | I10: =SUM(I5:I9) -> 32795.233 | J10: =SUM(J5:J9) -> 38333.954 | ... L10: =SUM(L5:L9) -> 54524.086
A12: I (PPE) | B12: Property, plant, and equipment | C12: =SUM('(BS)'!H17:H24) -> 53945 | D12: =SUM('(BS)'!I17:I24) -> 54668 | E12: =SUM('(BS)'!J17:J24) -> 57210 | F12: =SUM('(BS)'!K17:K24) -> 63776 | G12: =SUM('(BS)'!L17:L24) -> 70143 | H12: =G12+PPE!H6 -> 78236.247 | I12: =H12+PPE!I6 -> 87910.648 | J12: =I12+PPE!J6 -> 99114.132 | K12: =J12+PPE!K6 -> 110815.79 | L12: =K12+PPE!L6 -> 123184.82
A13: I (PPE) | B13: Intangible Assets | C13: ='(BS)'!H25 -> 6680 | D13: ='(BS)'!I25 -> 6375 | E13: ='(BS)'!J25 -> 6405 | F13: ='(BS)'!K25 -> 6484 | G13: ='(BS)'!L25 -> 6501 | H13: =G13+PPE!H29 -> 6638.8756 | I13: =H13+PPE!I29 -> 6845.4756 | J13: =I13+PPE!J29 -> 7051.8376 | K13: =J13+PPE!K29 -> 7239.9505 | L13: =K13+PPE!L29 -> 7419.7743
A14: I | B14: Other fixed assets | C14: ='(BS)'!H26 -> 5927 | D14: ='(BS)'!I26 -> 6289 | E14: ='(BS)'!J26 -> 6387 | F14: ='(BS)'!K26 -> 6695 | G14: ='(BS)'!L26 -> 6637 | H14: =G14 -> 6637 | I14: =H14 -> 6637 | J14: =I14 -> 6637 | K14: =J14 -> 6637 | L14: =K14 -> 6637
A15: I | B15: Capital Work In Progress | C15: ='(BS)'!H29 -> 920 | D15: ='(BS)'!I29 -> 1687 | E15: ='(BS)'!J29 -> 4785 | F15: ='(BS)'!K29 -> 4040 | G15: ='(BS)'!L29 -> 6811 | H15: =G15 -> 6811 | I15: =H15 -> 6811 | J15: =I15 -> 6811 | K15: =J15 -> 6811 | L15: =K15 -> 6811
A16: I | B16: Long Term Investment | C16: ='(BS)'!H30 -> 5929 | D16: ='(BS)'!I30 -> 12178 | E16: ='(BS)'!J30 -> 6336 | F16: ='(BS)'!K30 -> 7297 | G16: ='(BS)'!L30 -> 8249 | H16: =G16 -> 8249 | I16: =H16 -> 8249 | J16: =I16 -> 8249 | K16: =J16 -> 8249 | L16: =K16 -> 8249
A17: I | B17: Accumulated Depreciation | C17: ='(BS)'!H28 -> 9399 | D17: ='(BS)'!I28 -> 11921 | E17: ='(BS)'!J28 -> 14514 | F17: ='(BS)'!K28 -> 17378 | G17: ='(BS)'!L28 -> 20403 | H17: =G17+PPE!H16 -> 23914.217 | I17: =H17+PPE!I16 -> 27645.863 | J17: =I17+PPE!J16 -> 31694.134 | K17: =J17+PPE!K16 -> 36103.884 | L17: =K17+PPE!L16 -> 40897.545
B18: Non Current Assets | C18: =SUM(C12:C16)-C17 -> 64002 | D18: =SUM(D12:D16)-D17 -> 69276 | E18: =SUM(E12:E16)-E17 -> 66609 | F18: =SUM(F12:F16)-F17 -> 70914 | G18: =SUM(G12:G16)-G17 -> 77938 | H18: =SUM(H12:H16)-H17 -> 82657.906 | I18: =SUM(I12:I16)-I17 -> 88807.261 | J18: =SUM(J12:J16)-J17 -> 96168.837 | ... L18: =SUM(L12:L16)-L17 -> 111404.05
B19: Total Assets | C19: =C10+C18 -> 79216 | D19: =D10+D18 -> 86176 | E19: =E10+E18 -> 83813 | F19: =F10+F18 -> 91379 | G19: =G10+G18 -> 100797 | H19: =H10+H18 -> 109734.83 | I19: =I10+I18 -> 121602.49 | J19: =J10+J18 -> 134502.79 | ... L19: =L10+L18 -> 165928.14
A21: O | B21: Trade Payables | C21: ='(BS)'!H12 -> 3363 | D21: ='(BS)'!I12 -> 4548 | E21: ='(BS)'!J12 -> 5863 | F21: ='(BS)'!K12 -> 7209 | G21: ='(BS)'!L12 -> 8478 | H21: =WC!H11 -> 8699.5767 | I21: =WC!I11 -> 10152.406 | J21: =WC!J11 -> 11746.334 | K21: =WC!K11 -> 13473.045 | L21: =WC!L11 -> 15318.852
A22: O | B22: Advance from Customers | C22: ='(BS)'!H13 -> 464 | D22: ='(BS)'!I13 -> 415 | E22: ='(BS)'!J13 -> 465 | F22: ='(BS)'!K13 -> 384 | G22: ='(BS)'!L13 -> 527 | H22: =WC!H12 -> 704.35318 | I22: =WC!I12 -> 821.98016 | J22: =WC!J12 -> 951.03105 | K22: =WC!K12 -> 1090.8326 | L22: =WC!L12 -> 1240.2767
A23: O | B23: Other liability items | C23: ='(BS)'!H14 -> 13316 | D23: ='(BS)'!I14 -> 15313 | E23: ='(BS)'!J14 -> 15753 | F23: ='(BS)'!K14 -> 18349 | G23: ='(BS)'!L14 -> 20106 | H23: =WC!H13 -> 20106 | I23: =WC!I13 -> 20106 | J23: =WC!J13 -> 20106 | K23: =WC!K13 -> 20106 | L23: =WC!L13 -> 20106
A24: F | B24: Short term Borrowings | C24: ='(BS)'!H7 -> 4106 | D24: ='(BS)'!I7 -> 6939 | E24: ='(BS)'!J7 -> 4900 | F24: ='(BS)'!K7 -> 4544 | G24: ='(BS)'!L7 -> 4991 | H24: =Drivers!H32 -> 5096 | I24: =Drivers!I32 -> 5294 | J24: =Drivers!J32 -> 4965 | K24: =Drivers!K32 -> 4978 | L24: =Drivers!L32 -> 5064.8
B25: Current Liabilities | C25: =SUM(C21:C24) -> 21249 | D25: =SUM(D21:D24) -> 27215 | E25: =SUM(E21:E24) -> 26981 | F25: =SUM(F21:F24) -> 30486 | G25: =SUM(G21:G24) -> 34102 | H25: =SUM(H21:H24) -> 34605.93 | I25: =SUM(I21:I24) -> 36374.386 | J25: =SUM(J21:J24) -> 37768.365 | ... L25: =SUM(L21:L24) -> 41729.929
A27: F | B27: Long term Borrowings | C27: ='(BS)'!H6 -> 17368 | D27: ='(BS)'!I6 -> 13548 | E27: ='(BS)'!J6 -> 5303 | F27: ='(BS)'!K6 -> 5356 | G27: ='(BS)'!L6 -> 5308 | H27: =Drivers!H33 -> 5322.3333 | I27: =Drivers!I33 -> 5328.7778 | J27: =Drivers!J33 -> 5319.7037 | K27: =Drivers!K33 -> 5323.6049 | L27: =Drivers!L33 -> 5324.0288
A28: F | B28: Lease Liabilities | C28: ='(BS)'!H8 -> 0 | D28: ='(BS)'!I8 -> 1232 | E28: ='(BS)'!J8 -> 1096 | F28: ='(BS)'!K8 -> 1157 | G28: ='(BS)'!L8 -> 1103 | H28: =G28 -> 1103 | I28: =H28 -> 1103 | J28: =I28 -> 1103 | K28: =J28 -> 1103 | L28: =K28 -> 1103
A29: F | B29: Other Borrowings | C29: ='(BS)'!H9 -> 1545 | D29: ='(BS)'!I9 -> 0 | E29: ='(BS)'!J9 -> 0 | F29: ='(BS)'!K9 -> 0 | G29: ='(BS)'!L9 -> 0 | H29: =G29 -> 0 | I29: =H29 -> 0 | J29: =I29 -> 0 | K29: =J29 -> 0 | L29: =K29 -> 0
B30: Non Current Liabilities | C30: =SUM(C27:C29) -> 18913 | D30: =SUM(D27:D29) -> 14780 | E30: =SUM(E27:E29) -> 6399 | F30: =SUM(F27:F29) -> 6513 | G30: =SUM(G27:G29) -> 6411 | H30: =SUM(H27:H29) -> 6425.3333 | I30: =SUM(I27:I29) -> 6431.7778 | J30: =SUM(J27:J29) -> 6422.7037 | ... L30: =SUM(L27:L29) -> 6427.0288
B31: Total Liabilities | C31: =C25+C30 -> 40162 | D31: =D25+D30 -> 41995 | E31: =E25+E30 -> 33380 | F31: =F25+F30 -> 36999 | G31: =G25+G30 -> 40513 | H31: =H25+H30 -> 41031.263 | I31: =I25+I30 -> 42806.164 | J31: =J25+J30 -> 44191.068 | ... L31: =L25+L30 -> 48156.957
A33: F | B33: Equity Capital | C33: ='(BS)'!H3 -> 289 | D33: ='(BS)'!I3 -> 289 | E33: ='(BS)'!J3 -> 289 | F33: ='(BS)'!K3 -> 289 | G33: ='(BS)'!L3 -> 289 | H33: =G33 -> 289 | I33: =H33 -> 289 | J33: =I33 -> 289 | K33: =J33 -> 289 | L33: =K33 -> 289
A34: - | B34: Reserves | C34: ='(BS)'!H4 -> 38755 | D34: ='(BS)'!I4 -> 43886 | E34: ='(BS)'!J4 -> 50147 | F34: ='(BS)'!K4 -> 54036 | G34: ='(BS)'!L4 -> 59939 | H34: =G34+IS!H21 -> 68358.567 | I34: =H34+IS!I21 -> 78451.33 | J34: =I34+IS!J21 -> 89966.722 | K34: =J34+IS!K21 -> 102930.42 | L34: =K34+IS!L21 -> 117426.18
A35: F | B35: Non controlling int | C35: ='(BS)'!H11 -> 10 | D35: ='(BS)'!I11 -> 6 | E35: ='(BS)'!J11 -> -3 | F35: ='(BS)'!K11 -> 55 | G35: ='(BS)'!L11 -> 56 | H35: =G35 -> 56 | I35: =H35 -> 56 | J35: =I35 -> 56 | K35: =J35 -> 56 | L35: =K35 -> 56
